Workbook

Sheet Work Items
A1: Work Item ID | B1: Work Item | C1: Department | D1: Assigned To | E1: Opened Date | F1: Target Date | G1: Task Duration (days) | H1: Progress Status | I1: Overdue Flag | J1: Latest Note
A2: MKT-26-0001 | B2: Phase 2: coordinate creative asset review | C2: Marketing | D2: Ethan Brooks | E2: 46309 | F2: 46319 | G2: =F2-E2 -> 10 | H2: Not Started | I2: =AND(H2<>"Completed",F2<TODAY()) -> FALSE | J2: Scheduled for the next planning session.
A3: OPS-26-0002 | B3: Customer: review warehouse picking workflow | C3: Operations | D3: Sophie Taylor | E3: 46351 | F3: 46356 | G3: =F3-E3 -> 5 | H3: In Progress | I3: =AND(H3<>"Completed",F3<TODAY()) -> FALSE | J3: Draft prepared and awaiting feedback.
A4: TEC-26-0003 | B4: Phase 2: update application support notes | C4: Technology | D4: Noah Williams | E4: 46269 | F4: 46271 | G4: =F4-E4 -> 2 | H4: In Progress | I4: =AND(H4<>"Completed",F4<TODAY()) -> TRUE | J4: Initial review is complete.
A5: FIN-26-0004 | B5: FY27: update cash flow assumptions | C5: Finance | D5: Mia Nguyen | E5: 46324 | F5: 46345 | G5: =F5-E5 -> 21 | H5: In Progress | I5: =AND(H5<>"Completed",F5<TODAY()) -> FALSE | J5: A few items still need confirmation.
A6: MKT-26-0005 | B6: FY27: coordinate creative asset review | C6: Marketing | D6: Ethan Brooks | E6: 46291 | F6: 46302 | G6: =F6-E6 -> 11 | H6: In Progress | I6: =AND(H6<>"Completed",F6<TODAY()) -> TRUE | J6: Draft prepared and awaiting feedback.
A7: OPS-26-0006 | B7: Customer: coordinate regional delivery schedule | C7: Operations | D7: Oliver Chen | E7: 46323 | F7: 46327 | G7: =F7-E7 -> 4 | H7: On Hold | I7: =AND(H7<>"Completed",F7<TODAY()) -> FALSE | J7: Waiting for revised requirements.
A8: PPL-26-0007 | B8: Monthly: update workplace policy guide | C8: People & Culture | D8: Lucas Brown | E8: 46306 | F8: 46322 | G8: =F8-E8 -> 16 | H8: Completed | I8: =AND(H8<>"Completed",F8<TODAY()) -> FALSE | J8: Final version has been circulated.
A9: OPS-26-0008 | B9: Internal: update stock replenishment guide | C9: Operations | D9: Noah Williams | E9: 46295 | F9: 46297 | G9: =F9-E9 -> 2 | H9: Completed | I9: =AND(H9<>"Completed",F9<TODAY()) -> FALSE | J9: Closed after team review.
A10: STR-26-0009 | B10: Monthly: review project milestone risks | C10: Strategy | D10: Ethan Brooks | E10: 46304 | F10: 46315 | G10: =F10-E10 -> 11 | H10: In Progress | I10: =AND(H10<>"Completed",F10<TODAY()) -> FALSE | J10: Initial review is complete.
A11: CX-26-0010 | B11: Customer: review service quality sample | C11: Customer Experience | D11: Ava Thompson | E11: 46312 | F11: 46327 | G11: =F11-E11 -> 15 | H11: In Progress | I11: =AND(H11<>"Completed",F11<TODAY()) -> FALSE | J11: Work is underway; next update is due shortly.
A12: OPS-26-0011 | B12: Monthly: prepare weekly fulfilment summary | C12: Operations | D12: Jack Patel | E12: 46327 | F12: 46331 | G12: =F12-E12 -> 4 | H12: In Progress | I12: =AND(H12<>"Completed",F12<TODAY()) -> FALSE | J12: A few items still need confirmation.
A13: TEC-26-0012 | B13: Customer: prepare user acceptance test cases | C13: Technology | D13: Mia Nguyen | E13: 46337 | F13: 46347 | G13: =F13-E13 -> 10 | H13: Completed | I13: =AND(H13<>"Completed",F13<TODAY()) -> FALSE | J13: Deliverable accepted by the relevant lead.
... A181: MKT-26-0180 | B181: Coordinate creative asset review | C181: Marketing | D181: Mia Nguyen | E181: 46287 | F181: 46309 | G181: =F181-E181 -> 22 | H181: In Progress | I181: =AND(H181<>"Completed",F181<TODAY()) -> FALSE | J181: Initial review is complete.

Sheet DashBoard
C8: Total Work Iteams | F8: Completed | I8: In Progress | L8: Not Started
C9: =Names!B22 -> 179 | F9: =Names!B18 -> 51 | I9: =Names!B19 -> 82 | L9: =Names!B20 -> 28

Sheet Names
A1: {=_xlfn.UNIQUE('Work Items'!D2:D181)} -> Ethan Brooks
A2: Sophie Taylor
A3: Noah Williams
A4: Mia Nguyen
A5: Oliver Chen
A6: Lucas Brown
A7: Ava Thompson
A8: Jack Patel
A9: Priya Shah
A10: Amelia Wilson
A11: Isabella Martin
A12: Liam Carter
A17: Progress Status | B17: Count
A18: Completed | B18: =COUNTIF('Work Items'!H2:H181,Names!A18) -> 51
A19: In Progress | B19: =COUNTIF('Work Items'!H3:H182,Names!A19) -> 82
A20: Not started | B20: =COUNTIF('Work Items'!H4:H182,Names!A20) -> 28
A21: On Hold | B21: =COUNTIF('Work Items'!H5:H182,Names!A21) -> 18
A22: Total | B22: =SUM(B18:B21) -> 179
A26: Progress Status | B26: Count of Work Item ID
A27: Completed | B27: 51
A28: In Progress | B28: 82
A29: Not Started | B29: 29
A30: On Hold | B30: 18
A31: Grand Total | B31: 180
A35: Department | B35: Count of Work Item ID
A36: Customer Experience | B36: 19
A37: Finance | B37: 20
A38: Marketing | B38: 28
A39: Operations | B39: 27
A40: People & Culture | B40: 26
A41: Strategy | B41: 28
A42: Technology | B42: 32
A43: Grand Total | B43: 180
A47: Count of Work Item ID | B47: Progress Status
A48: Assigned To | B48: Completed | C48: In Progress | D48: Not Started | E48: On Hold | F48: Grand Total
A49: Amelia Wilson | B49: 9 | C49: 6 | D49: 5 | E49: 2 | F49: 22
A50: Ethan Brooks | B50: 5 | C50: 11 | D50: 3 | E50: 2 | F50: 21
A51: Liam Carter | B51: 4 | C51: 7 | D51: 5 | E51: 1 | F51: 17
A52: Priya Shah | B52: 8 | C52: 6 | D52: 3 | F52: 17
A53: Isabella Martin | B53: 4 | C53: 7 | D53: 2 | E53: 4 | F53: 17
...
